Workbook
Name Slicer_Category: #N/A
Name Slicer_Region: #N/A
Name Slicer_Salesperson: #N/A

Sheet Dashboard
H26: =GETPIVOTDATA("Total Sales",'Pivot Data'!$A$3) -> 4072350.1 | I26: =GETPIVOTDATA("Total Profit",'Pivot Data'!$A$3) -> 655542.86 | J26: =GETPIVOTDATA("Total Orders",'Pivot Data'!$A$3) -> 1500
T28: =ROUND(H26,0) -> 4072350
S33: =GETPIVOTDATA("Total Sales",'Pivot Data'!$A$3) -> 4072350.1 | T33: =GETPIVOTDATA("Total Orders",'Pivot Data'!$A$3) -> 1500
S34: =GETPIVOTDATA("Total Profit",'Pivot Data'!$A$3) -> 655542.86
C37: #VALUE!
S39: ='Pivot Data'!D4 -> 0.16097409

Sheet Raw data
A1: Date | B1: Region | C1: Product | D1: Column1 | E1: Column2 | F1: Category | G1: Quantity | H1: UnitPrice | I1: StoreLocation | J1: CustomerType | K1: Discount | L1: Salesperson | M1: TotalPrice | N1: PaymentMethod | O1: Promotion | P1: Returned | Q1: OrderID | R1: CustomerName | S1: ShippingCost | T1: OrderDate | U1: DeliveryDate | V1: RegionManager | W1: Net Sales | X1: Sales | Y1: Profit | Z1: Discount Category | AA1: Year-Month
A2: 44980 | B2: East | C2: Laptop | D2: =TRIM(Table1[[#This Row],[Product]]) -> Laptop | E2: =PROPER(Table1[[#This Row],[Column1]]) -> Laptop | F2: =IF(OR(E2="Chair",E2="Desk"),"Furniture",IF(OR(E2="Laptop",E2="Monitor",E2="Phone",E2="Tablet"),"Technology",IF(E2="Printer","Office Supplies","Other"))) -> Technology | G2: 14 | H2: 163.6 | I2: Store B | J2: Wholesale | K2: 0 | L2: Eva | M2: 2290.4 | N2: Online | O2: FREESHIP | P2: 0 | Q2: REG100000 | R2: Cust 6583 | S2: 43.34 | T2: 44980 | U2: 44984 | V2: Eric | W2: =M2*(1-K2) -> 2290.4 | X2: =G2*H2 -> 2290.4 | Y2: =X2-W2 -> 0 | Z2: =IF(K2=0,"No Discount",IF(K2<5%,"Low",IF(K2<15%,"Medium","High"))) -> No Discount | AA2: =DATE(YEAR(Table1[[#This Row],[OrderDate]]),MONTH(Table1[[#This Row],[OrderDate]]),1) -> 44958
A3: 45645 | B3: South | C3: Phone | D3: =TRIM(Table1[[#This Row],[Product]]) -> Phone | E3: =PROPER(Table1[[#This Row],[Column1]]) -> Phone | F3: =IF(OR(E3="Chair",E3="Desk"),"Furniture",IF(OR(E3="Laptop",E3="Monitor",E3="Phone",E3="Tablet"),"Technology",IF(E3="Printer","Office Supplies","Other"))) -> Technology | G3: 1 | H3: 544.01 | I3: Store A | J3: Retail | K3: 0 | L3: Alice | M3: 544.01 | N3: Gift Card | O3: SAVE10 | P3: 0 | Q3: REG100001 | R3: Cust 2144 | S3: 5.3 | T3: 45645 | U3: 45654 | V3: Sophie | W3: =M3*(1-K3) -> 544.01 | X3: =G3*H3 -> 544.01 | Y3: =X3-W3 -> 0 | AA3: =DATE(YEAR(Table1[[#This Row],[OrderDate]]),MONTH(Table1[[#This Row],[OrderDate]]),1) -> 45627
A4: 45056 | B4: North | C4: Desk | D4: =TRIM(Table1[[#This Row],[Product]]) -> Desk | E4: =PROPER(Table1[[#This Row],[Column1]]) -> Desk | F4: =IF(OR(E4="Chair",E4="Desk"),"Furniture",IF(OR(E4="Laptop",E4="Monitor",E4="Phone",E4="Tablet"),"Technology",IF(E4="Printer","Office Supplies","Other"))) -> Furniture | G4: 14 | H4: 346.18 | I4: Store B | J4: Wholesale | K4: 0.1 | L4: Alice | M4: 4361.868 | N4: Online | O4: WINTER15 | P4: 0 | Q4: REG100002 | R4: Cust 5998 | S4: 20.46 | T4: 45056 | U4: 45065 | V4: Ryan | W4: =M4*(1-K4) -> 3925.6812 | X4: =G4*H4 -> 4846.52 | Y4: =X4-W4 -> 920.8388 | Z4: =IF(K4=0,"No Discount",IF(K4<5%,"Low",IF(K4<15%,"Medium","High"))) -> Medium | AA4: =DATE(YEAR(Table1[[#This Row],[OrderDate]]),MONTH(Table1[[#This Row],[OrderDate]]),1) -> 45047
A5: 45714 | B5: Central | C5: Chair | D5: =TRIM(Table1[[#This Row],[Product]]) -> Chair | E5: =PROPER(Table1[[#This Row],[Column1]]) -> Chair | F5: =IF(OR(E5="Chair",E5="Desk"),"Furniture",IF(OR(E5="Laptop",E5="Monitor",E5="Phone",E5="Tablet"),"Technology",IF(E5="Printer","Office Supplies","Other"))) -> Furniture | G5: 18 | H5: 384.82 | I5: Store A | J5: Wholesale | K5: 0.15 | L5: Frank | M5: 5887.746 | N5: Gift Card | O5: FREESHIP | P5: 0 | Q5: REG100003 | R5: Cust 7136 | S5: 27.95 | T5: 45714 | U5: 45718 | V5: Cameron | W5: =M5*(1-K5) -> 5004.5841 | X5: =G5*H5 -> 6926.76 | Y5: =X5-W5 -> 1922.1759 | Z5: =IF(K5=0,"No Discount",IF(K5<5%,"Low",IF(K5<15%,"Medium","High"))) -> High | AA5: =DATE(YEAR(Table1[[#This Row],[OrderDate]]),MONTH(Table1[[#This Row],[OrderDate]]),1) -> 45689
A6: 45101 | B6: East | C6: Desk | D6: =TRIM(Table1[[#This Row],[Product]]) -> Desk | E6: =PROPER(Table1[[#This Row],[Column1]]) -> Desk | F6: =IF(OR(E6="Chair",E6="Desk"),"Furniture",IF(OR(E6="Laptop",E6="Monitor",E6="Phone",E6="Tablet"),"Technology",IF(E6="Printer","Office Supplies","Other"))) -> Furniture | G6: 18 | H6: 237.76 | I6: Store C | J6: Retail | K6: 0 | L6: Carlos | M6: 4279.68 | N6: Online | O6: SAVE10 | P6: 0 | Q6: REG100004 | R6: Cust 6506 | S6: 5.73 | T6: 45101 | U6: 45104 | V6: Eric | W6: =M6*(1-K6) -> 4279.68 | X6: =G6*H6 -> 4279.68 | Y6: =X6-W6 -> 0 | Z6: =IF(K6=0,"No Discount",IF(K6<5%,"Low",IF(K6<15%,"Medium","High"))) -> No Discount | AA6: =DATE(YEAR(Table1[[#This Row],[OrderDate]]),MONTH(Table1[[#This Row],[OrderDate]]),1) -> 45078
A7: 45342 | B7: Central | C7: Monitor | D7: =TRIM(Table1[[#This Row],[Product]]) -> Monitor | E7: =PROPER(Table1[[#This Row],[Column1]]) -> Monitor | F7: =IF(OR(E7="Chair",E7="Desk"),"Furniture",IF(OR(E7="Laptop",E7="Monitor",E7="Phone",E7="Tablet"),"Technology",IF(E7="Printer","Office Supplies","Other"))) -> Technology | G7: 2 | H7: 385.09 | I7: Store D | J7: Wholesale | K7: 0.15 | L7: Diana | M7: 654.653 | N7: Credit Card | P7: 0 | Q7: REG100005 | R7: Cust 3909 | S7: 11.92 | T7: 45342 | U7: 45352 | V7: Cameron | W7: =M7*(1-K7) -> 556.45505 | X7: =G7*H7 -> 770.18 | Y7: =X7-W7 -> 213.72495 | Z7: =IF(K7=0,"No Discount",IF(K7<5%,"Low",IF(K7<15%,"Medium","High"))) -> High | AA7: =DATE(YEAR(Table1[[#This Row],[OrderDate]]),MONTH(Table1[[#This Row],[OrderDate]]),1) -> 45323
A8: 44937 | B8: South | C8: Chair | D8: =TRIM(Table1[[#This Row],[Product]]) -> Chair | E8: =PROPER(Table1[[#This Row],[Column1]]) -> Chair | F8: =IF(OR(E8="Chair",E8="Desk"),"Furniture",IF(OR(E8="Laptop",E8="Monitor",E8="Phone",E8="Tablet"),"Technology",IF(E8="Printer","Office Supplies","Other"))) -> Furniture | G8: 7 | H8: 17.5 | I8: Store C | J8: Retail | K8: 0.1 | L8: Alice | M8: 110.25 | N8: Debit Card | O8: WINTER15 | P8: 0 | Q8: REG100006 | R8: Cust 7887 | S8: 5.02 | T8: 44937 | U8: 44940 | V8: Sophie | W8: =M8*(1-K8) -> 99.225 | X8: =G8*H8 -> 122.5 | Y8: =X8-W8 -> 23.275 | Z8: =IF(K8=0,"No Discount",IF(K8<5%,"Low",IF(K8<15%,"Medium","High"))) -> Medium | AA8: =DATE(YEAR(Table1[[#This Row],[OrderDate]]),MONTH(Table1[[#This Row],[OrderDate]]),1) -> 44927
A9: 44935 | B9: Central | C9: Chair | D9: =TRIM(Table1[[#This Row],[Product]]) -> Chair | E9: =PROPER(Table1[[#This Row],[Column1]]) -> Chair | F9: =IF(OR(E9="Chair",E9="Desk"),"Furniture",IF(OR(E9="Laptop",E9="Monitor",E9="Phone",E9="Tablet"),"Technology",IF(E9="Printer","Office Supplies","Other"))) -> Furniture | G9: 3 | H9: 330.22 | I9: Store C | J9: Wholesale | K9: 0.15 | L9: Carlos | M9: 842.061 | N9: Cash | P9: 0 | Q9: REG100007 | R9: Cust 5301 | S9: 48.01 | T9: 44935 | U9: 44937 | V9: Cameron | W9: =M9*(1-K9) -> 715.75185 | X9: =G9*H9 -> 990.66 | Y9: =X9-W9 -> 274.90815 | Z9: =IF(K9=0,"No Discount",IF(K9<5%,"Low",IF(K9<15%,"Medium","High"))) -> High | AA9: =DATE(YEAR(Table1[[#This Row],[OrderDate]]),MONTH(Table1[[#This Row],[OrderDate]]),1) -> 44927
A10: 45581 | B10: South | C10: Chair | D10: =TRIM(Table1[[#This Row],[Product]]) -> Chair | E10: =PROPER(Table1[[#This Row],[Column1]]) -> Chair | F10: =IF(OR(E10="Chair",E10="Desk"),"Furniture",IF(OR(E10="Laptop",E10="Monitor",E10="Phone",E10="Tablet"),"Technology",IF(E10="Printer","Office Supplies","Other"))) -> Furniture | G10: 3 | H10: 432.04 | I10: Store D | J10: Wholesale | K10: 0.05 | L10: Bob | M10: 1231.314 | N10: Debit Card | O10: FREESHIP | P10: 1 | Q10: REG100008 | R10: Cust 2284 | S10: 42.11 | T10: 45581 | U10: 45583 | V10: Sophie | W10: =M10*(1-K10) -> 1169.7483 | X10: =G10*H10 -> 1296.12 | Y10: =X10-W10 -> 126.3717 | Z10: =IF(K10=0,"No Discount",IF(K10<5%,"Low",IF(K10<15%,"Medium","High"))) -> Medium | AA10: =DATE(YEAR(Table1[[#This Row],[OrderDate]]),MONTH(Table1[[#This Row],[OrderDate]]),1) -> 45566
A11: 45721 | B11: West | C11: Desk | D11: =TRIM(Table1[[#This Row],[Product]]) -> Desk | E11: =PROPER(Table1[[#This Row],[Column1]]) -> Desk | F11: =IF(OR(E11="Chair",E11="Desk"),"Furniture",IF(OR(E11="Laptop",E11="Monitor",E11="Phone",E11="Tablet"),"Technology",IF(E11="Printer","Office Supplies","Other"))) -> Furniture | G11: 5 | H11: 323.28 | I11: Store D | J11: Retail | K11: 0.1 | L11: Frank | M11: 1454.76 | N11: Gift Card | O11: SAVE10 | P11: 0 | Q11: REG100009 | R11: Cust 3732 | S11: 41.1 | T11: 45721 | U11: 45729 | V11: Wendy | W11: =M11*(1-K11) -> 1309.284 | X11: =G11*H11 -> 1616.4 | Y11: =X11-W11 -> 307.116 | Z11: =IF(K11=0,"No Discount",IF(K11<5%,"Low",IF(K11<15%,"Medium","High"))) -> Medium | AA11: =DATE(YEAR(Table1[[#This Row],[OrderDate]]),MONTH(Table1[[#This Row],[OrderDate]]),1) -> 45717
A12: 45392 | B12: North | C12: Desk | D12: =TRIM(Table1[[#This Row],[Product]]) -> Desk | E12: =PROPER(Table1[[#This Row],[Column1]]) -> Desk | F12: =IF(OR(E12="Chair",E12="Desk"),"Furniture",IF(OR(E12="Laptop",E12="Monitor",E12="Phone",E12="Tablet"),"Technology",IF(E12="Printer","Office Supplies","Other"))) -> Furniture | G12: 15 | H12: 523.29 | I12: Store B | J12: Wholesale | K12: 0.15 | L12: Eva | M12: 6671.9475 | N12: Debit Card | P12: 0 | Q12: REG100010 | R12: Cust 1462 | S12: 12.14 | T12: 45392 | U12: 45399 | V12: Ryan | W12: =M12*(1-K12) -> 5671.1554 | X12: =G12*H12 -> 7849.35 | Y12: =X12-W12 -> 2178.1946 | Z12: =IF(K12=0,"No Discount",IF(K12<5%,"Low",IF(K12<15%,"Medium","High"))) -> High | AA12: =DATE(YEAR(Table1[[#This Row],[OrderDate]]),MONTH(Table1[[#This Row],[OrderDate]]),1) -> 45383
A13: 45485 | B13: East | C13: Phone | D13: =TRIM(Table1[[#This Row],[Product]]) -> Phone | E13: =PROPER(Table1[[#This Row],[Column1]]) -> Phone | F13: =IF(OR(E13="Chair",E13="Desk"),"Furniture",IF(OR(E13="Laptop",E13="Monitor",E13="Phone",E13="Tablet"),"Technology",IF(E13="Printer","Office Supplies","Other"))) -> Technology | G13: 19 | H13: 207.35 | I13: Store D | J13: Retail | K13: 0.1 | L13: Eva | M13: 3545.685 | N13: Gift Card | P13: 1 | Q13: REG100011 | R13: Cust 4330 | S13: 44.89 | T13: 45485 | U13: 45491 | V13: Eric | W13: =M13*(1-K13) -> 3191.1165 | X13: =G13*H13 -> 3939.65 | Y13: =X13-W13 -> 748.5335 | Z13: =IF(K13=0,"No Discount",IF(K13<5%,"Low",IF(K13<15%,"Medium","High"))) -> Medium | AA13: =DATE(YEAR(Table1[[#This Row],[OrderDate]]),MONTH(Table1[[#This Row],[OrderDate]]),1) -> 45474
A14: 45128 | B14: Central | C14: Phone | D14: =TRIM(Table1[[#This Row],[Product]]) -> Phone | E14: =PROPER(Table1[[#This Row],[Column1]]) -> Phone | F14: =IF(OR(E14="Chair",E14="Desk"),"Furniture",IF(OR(E14="Laptop",E14="Monitor",E14="Phone",E14="Tablet"),"Technology",IF(E14="Printer","Office Supplies","Other"))) -> Technology | G14: 1 | H14: 120.53 | I14: Store B | J14: Retail | K14: 0.05 | L14: Diana | M14: 114.5035 | N14: Cash | O14: WINTER15 | P14: 0 | Q14: REG100012 | R14: Cust 2372 | S14: 20.35 | T14: 45128 | U14: 45138 | V14: Cameron | W14: =M14*(1-K14) -> 108.77832 | X14: =G14*H14 -> 120.53 | Y14: =X14-W14 -> 11.751675 | Z14: =IF(K14=0,"No Discount",IF(K14<5%,"Low",IF(K14<15%,"Medium","High"))) -> Medium | AA14: =DATE(YEAR(Table1[[#This Row],[OrderDate]]),MONTH(Table1[[#This Row],[OrderDate]]),1) -> 45108
A15: 45675 | B15: West | C15: Tablet | D15: =TRIM(Table1[[#This Row],[Product]]) -> Tablet | E15: =PROPER(Table1[[#This Row],[Column1]]) -> Tablet | F15: =IF(OR(E15="Chair",E15="Desk"),"Furniture",IF(OR(E15="Laptop",E15="Monitor",E15="Phone",E15="Tablet"),"Technology",IF(E15="Printer","Office Supplies","Other"))) -> Technology | G15: 1 | H15: 157.83 | I15: Store A | J15: Wholesale | K15: 0.15 | L15: Carlos | M15: 134.1555 | N15: Debit Card | P15: 0 | Q15: REG100013 | R15: Cust 4672 | S15: 42.82 | T15: 45675 | U15: 45679 | V15: Wendy | W15: =M15*(1-K15) -> 114.03217 | X15: =G15*H15 -> 157.83 | Y15: =X15-W15 -> 43.797825 | Z15: =IF(K15=0,"No Discount",IF(K15<5%,"Low",IF(K15<15%,"Medium","High"))) -> High | AA15: =DATE(YEAR(Table1[[#This Row],[OrderDate]]),MONTH(Table1[[#This Row],[OrderDate]]),1) -> 45658
A16: 45634 | B16: North | C16: Desk | D16: =TRIM(Table1[[#This Row],[Product]]) -> Desk | E16: =PROPER(Table1[[#This Row],[Column1]]) -> Desk | F16: =IF(OR(E16="Chair",E16="Desk"),"Furniture",IF(OR(E16="Laptop",E16="Monitor",E16="Phone",E16="Tablet"),"Technology",IF(E16="Printer","Office Supplies","Other"))) -> Furniture | G16: 15 | H16: 220.3 | I16: Store B | J16: Retail | K16: 0.15 | L16: Diana | M16: 2808.825 | N16: Debit Card | P16: 0 | Q16: REG100014 | R16: Cust 4548 | S16: 39.66 | T16: 45634 | U16: 45641 | V16: Ryan | W16: =M16*(1-K16) -> 2387.5012 | X16: =G16*H16 -> 3304.5 | Y16: =X16-W16 -> 916.99875 | Z16: =IF(K16=0,"No Discount",IF(K16<5%,"Low",IF(K16<15%,"Medium","High"))) -> High | AA16: =DATE(YEAR(Table1[[#This Row],[OrderDate]]),MONTH(Table1[[#This Row],[OrderDate]]),1) -> 45627
A17: 45788 | B17: West | C17: Chair | D17: =TRIM(Table1[[#This Row],[Product]]) -> Chair | E17: =PROPER(Table1[[#This Row],[Column1]]) -> Chair | F17: =IF(OR(E17="Chair",E17="Desk"),"Furniture",IF(OR(E17="Laptop",E17="Monitor",E17="Phone",E17="Tablet"),"Technology",IF(E17="Printer","Office Supplies","Other"))) -> Furniture | G17: 17 | H17: 162.96 | I17: Store A | J17: Wholesale | K17: 0.05 | L17: Eva | M17: 2631.804 | N17: Gift Card | O17: FREESHIP | P17: 0 | Q17: REG100015 | R17: Cust 7037 | S17: 8.11 | T17: 45788 | U17: 45794 | V17: Wendy | W17: =M17*(1-K17) -> 2500.2138 | X17: =G17*H17 -> 2770.32 | Y17: =X17-W17 -> 270.1062 | Z17: =IF(K17=0,"No Discount",IF(K17<5%,"Low",IF(K17<15%,"Medium","High"))) -> Medium | AA17: =DATE(YEAR(Table1[[#This Row],[OrderDate]]),MONTH(Table1[[#This Row],[OrderDate]]),1) -> 45778
A18: 44983 | B18: West | C18: Laptop | D18: =TRIM(Table1[[#This Row],[Product]]) -> Laptop | E18: =PROPER(Table1[[#This Row],[Column1]]) -> Laptop | F18: =IF(OR(E18="Chair",E18="Desk"),"Furniture",IF(OR(E18="Laptop",E18="Monitor",E18="Phone",E18="Tablet"),"Technology",IF(E18="Printer","Office Supplies","Other"))) -> Technology | G18: 19 | H18: 236.11 | I18: Store D | J18: Wholesale | K18: 0 | L18: Bob | M18: 4486.09 | N18: Online | O18: WINTER15 | P18: 0 | Q18: REG100016 | R18: Cust 4975 | S18: 34.11 | T18: 44983 | U18: 44989 | V18: Wendy | W18: =M18*(1-K18) -> 4486.09 | X18: =G18*H18 -> 4486.09 | Y18: =X18-W18 -> 0 | Z18: =IF(K18=0,"No Discount",IF(K18<5%,"Low",IF(K18<15%,"Medium","High"))) -> No Discount | AA18: =DATE(YEAR(Table1[[#This Row],[OrderDate]]),MONTH(Table1[[#This Row],[OrderDate]]),1) -> 44958
A19: 45440 | B19: Central | C19: Desk | D19: =TRIM(Table1[[#This Row],[Product]]) -> Desk | E19: =PROPER(Table1[[#This Row],[Column1]]) -> Desk | F19: =IF(OR(E19="Chair",E19="Desk"),"Furniture",IF(OR(E19="Laptop",E19="Monitor",E19="Phone",E19="Tablet"),"Technology",IF(E19="Printer","Office Supplies","Other"))) -> Furniture | G19: 11 | H19: 573.14 | I19: Store D | J19: Retail | K19: 0.05 | L19: Diana | M19: 5989.313 | N19: Cash | O19: SAVE10 | P19: 0 | Q19: REG100017 | R19: Cust 8014 | S19: 34.71 | T19: 45440 | U19: 45444 | V19: Cameron | W19: =M19*(1-K19) -> 5689.8474 | X19: =G19*H19 -> 6304.54 | Y19: =X19-W19 -> 614.69265 | Z19: =IF(K19=0,"No Discount",IF(K19<5%,"Low",IF(K19<15%,"Medium","High"))) -> Medium | AA19: =DATE(YEAR(Table1[[#This Row],[OrderDate]]),MONTH(Table1[[#This Row],[OrderDate]]),1) -> 45413
A20: 45260 | B20: East | C20: Phone | D20: =TRIM(Table1[[#This Row],[Product]]) -> Phone | E20: =PROPER(Table1[[#This Row],[Column1]]) -> Phone | F20: =IF(OR(E20="Chair",E20="Desk"),"Furniture",IF(OR(E20="Laptop",E20="Monitor",E20="Phone",E20="Tablet"),"Technology",IF(E20="Printer","Office Supplies","Other"))) -> Technology | G20: 20 | H20: 519.04 | I20: Store B | J20: Retail | K20: 0.15 | L20: Carlos | M20: 8823.68 | N20: Gift Card | O20: FREESHIP | P20: 0 | Q20: REG100018 | R20: Cust 1228 | S20: 19.43 | T20: 45260 | U20: 45268 | V20: Eric | W20: =M20*(1-K20) -> 7500.128 | X20: =G20*H20 -> 10380.8 | Y20: =X20-W20 -> 2880.672 | Z20: =IF(K20=0,"No Discount",IF(K20<5%,"Low",IF(K20<15%,"Medium","High"))) -> High | AA20: =DATE(YEAR(Table1[[#This Row],[OrderDate]]),MONTH(Table1[[#This Row],[OrderDate]]),1) -> 45231
A21: 45099 | B21: West | C21: Desk | D21: =TRIM(Table1[[#This Row],[Product]]) -> Desk | E21: =PROPER(Table1[[#This Row],[Column1]]) -> Desk | F21: =IF(OR(E21="Chair",E21="Desk"),"Furniture",IF(OR(E21="Laptop",E21="Monitor",E21="Phone",E21="Tablet"),"Technology",IF(E21="Printer","Office Supplies","Other"))) -> Furniture | G21: 14 | H21: 30.83 | I21: Store B | J21: Retail | K21: 0 | L21: Carlos | M21: 431.62 | N21: Online | O21: WINTER15 | P21: 1 | Q21: REG100019 | R21: Cust 4247 | S21: 7.1 | T21: 45099 | U21: 45109 | V21: Wendy | W21: =M21*(1-K21) -> 431.62 | X21: =G21*H21 -> 431.62 | Y21: =X21-W21 -> 0 | Z21: =IF(K21=0,"No Discount",IF(K21<5%,"Low",IF(K21<15%,"Medium","High"))) -> No Discount | AA21: =DATE(YEAR(Table1[[#This Row],[OrderDate]]),MONTH(Table1[[#This Row],[OrderDate]]),1) -> 45078
A22: 45813 | B22: West | C22: Phone | D22: =TRIM(Table1[[#This Row],[Product]]) -> Phone | E22: =PROPER(Table1[[#This Row],[Column1]]) -> Phone | F22: =IF(OR(E22="Chair",E22="Desk"),"Furniture",IF(OR(E22="Laptop",E22="Monitor",E22="Phone",E22="Tablet"),"Technology",IF(E22="Printer","Office Supplies","Other"))) -> Technology | G22: 10 | H22: 319.05 | I22: Store D | J22: Wholesale | K22: 0 | L22: Diana | M22: 3190.5 | N22: Online | P22: 0 | Q22: REG100020 | R22: Cust 4199 | S22: 28.43 | T22: 45813 | U22: 45816 | V22: Wendy | W22: =M22*(1-K22) -> 3190.5 | X22: =G22*H22 -> 3190.5 | Y22: =X22-W22 -> 0 | Z22: =IF(K22=0,"No Discount",IF(K22<5%,"Low",IF(K22<15%,"Medium","High"))) -> No Discount | AA22: =DATE(YEAR(Table1[[#This Row],[OrderDate]]),MONTH(Table1[[#This Row],[OrderDate]]),1) -> 45809
A23: 44988 | B23: Central | C23: Chair | D23: =TRIM(Table1[[#This Row],[Product]]) -> Chair | E23: =PROPER(Table1[[#This Row],[Column1]]) -> Chair | F23: =IF(OR(E23="Chair",E23="Desk"),"Furniture",IF(OR(E23="Laptop",E23="Monitor",E23="Phone",E23="Tablet"),"Technology",IF(E23="Printer","Office Supplies","Other"))) -> Furniture | G23: 14 | H23: 312.79 | I23: Store A | J23: Retail | K23: 0.05 | L23: Bob | M23: 4160.107 | N23: Online | P23: 1 | Q23: REG100021 | R23: Cust 4186 | S23: 46.83 | T23: 44988 | U23: 44993 | V23: Cameron | W23: =M23*(1-K23) -> 3952.1016 | X23: =G23*H23 -> 4379.06 | Y23: =X23-W23 -> 426.95835 | Z23: =IF(K23=0,"No Discount",IF(K23<5%,"Low",IF(K23<15%,"Medium","High"))) -> Medium | AA23: =DATE(YEAR(Table1[[#This Row],[OrderDate]]),MONTH(Table1[[#This Row],[OrderDate]]),1) -> 44986
A24: 45340 | B24: North | C24: Laptop | D24: =TRIM(Table1[[#This Row],[Product]]) -> Laptop | E24: =PROPER(Table1[[#This Row],[Column1]]) -> Laptop | F24: =IF(OR(E24="Chair",E24="Desk"),"Furniture",IF(OR(E24="Laptop",E24="Monitor",E24="Phone",E24="Tablet"),"Technology",IF(E24="Printer","Office Supplies","Other"))) -> Technology | G24: 14 | H24: 395.45 | I24: Store C | J24: Retail | K24: 0 | L24: Carlos | M24: 5536.3 | N24: Cash | O24: FREESHIP | P24: 1 | Q24: REG100022 | R24: Cust 8137 | S24: 36.45 | T24: 45340 | U24: 45344 | V24: Ryan | W24: =M24*(1-K24) -> 5536.3 | X24: =G24*H24 -> 5536.3 | Y24: =X24-W24 -> 0 | Z24: =IF(K24=0,"No Discount",IF(K24<5%,"Low",IF(K24<15%,"Medium","High"))) -> No Discount | AA24: =DATE(YEAR(Table1[[#This Row],[OrderDate]]),MONTH(Table1[[#This Row],[OrderDate]]),1) -> 45323
A25: 45144 | B25: Central | C25: Laptop | D25: =TRIM(Table1[[#This Row],[Product]]) -> Laptop | E25: =PROPER(Table1[[#This Row],[Column1]]) -> Laptop | F25: =IF(OR(E25="Chair",E25="Desk"),"Furniture",IF(OR(E25="Laptop",E25="Monitor",E25="Phone",E25="Tablet"),"Technology",IF(E25="Printer","Office Supplies","Other"))) -> Technology | G25: 12 | H25: 472.72 | I25: Store D | J25: Retail | K25: 0.15 | L25: Diana | M25: 4821.744 | N25: Credit Card | P25: 0 | Q25: REG100023 | R25: Cust 4638 | S25: 27.97 | T25: 45144 | U25: 45152 | V25: Cameron | W25: =M25*(1-K25) -> 4098.4824 | X25: =G25*H25 -> 5672.64 | Y25: =X25-W25 -> 1574.1576 | Z25: =IF(K25=0,"No Discount",IF(K25<5%,"Low",IF(K25<15%,"Medium","High"))) -> High | AA25: =DATE(YEAR(Table1[[#This Row],[OrderDate]]),MONTH(Table1[[#This Row],[OrderDate]]),1) -> 45139
A26: 45435 | B26: North | C26: Desk | D26: =TRIM(Table1[[#This Row],[Product]]) -> Desk | E26: =PROPER(Table1[[#This Row],[Column1]]) -> Desk | F26: =IF(OR(E26="Chair",E26="Desk"),"Furniture",IF(OR(E26="Laptop",E26="Monitor",E26="Phone",E26="Tablet"),"Technology",IF(E26="Printer","Office Supplies","Other"))) -> Furniture | G26: 5 | H26: 288.01 | I26: Store A | J26: Wholesale | K26: 0 | L26: Eva | M26: 1440.05 | N26: Credit Card | O26: FREESHIP | P26: 0 | Q26: REG100024 | R26: Cust 8538 | S26: 46.69 | T26: 45435 | U26: 45442 | V26: Ryan | W26: =M26*(1-K26) -> 1440.05 | X26: =G26*H26 -> 1440.05 | Y26: =X26-W26 -> 0 | Z26: =IF(K26=0,"No Discount",IF(K26<5%,"Low",IF(K26<15%,"Medium","High"))) -> No Discount | AA26: =DATE(YEAR(Table1[[#This Row],[OrderDate]]),MONTH(Table1[[#This Row],[OrderDate]]),1) -> 45413
A27: 45222 | B27: East | C27: Phone | D27: =TRIM(Table1[[#This Row],[Product]]) -> Phone | E27: =PROPER(Table1[[#This Row],[Column1]]) -> Phone | F27: =IF(OR(E27="Chair",E27="Desk"),"Furniture",IF(OR(E27="Laptop",E27="Monitor",E27="Phone",E27="Tablet"),"Technology",IF(E27="Printer","Office Supplies","Other"))) -> Technology | G27: 13 | H27: 562.29 | I27: Store D | J27: Retail | K27: 0 | L27: Diana | M27: 7309.77 | N27: Gift Card | O27: SAVE10 | P27: 0 | Q27: REG100025 | R27: Cust 6322 | S27: 38.13 | T27: 45222 | U27: 45227 | V27: Eric | W27: =M27*(1-K27) -> 7309.77 | X27: =G27*H27 -> 7309.77 | Y27: =X27-W27 -> 0 | Z27: =IF(K27=0,"No Discount",IF(K27<5%,"Low",IF(K27<15%,"Medium","High"))) -> No Discount | AA27: =DATE(YEAR(Table1[[#This Row],[OrderDate]]),MONTH(Table1[[#This Row],[OrderDate]]),1) -> 45200
A28: 45824 | B28: West | C28: Phone | D28: =TRIM(Table1[[#This Row],[Product]]) -> Phone | E28: =PROPER(Table1[[#This Row],[Column1]]) -> Phone | F28: =IF(OR(E28="Chair",E28="Desk"),"Furniture",IF(OR(E28="Laptop",E28="Monitor",E28="Phone",E28="Tablet"),"Technology",IF(E28="Printer","Office Supplies","Other"))) -> Technology | G28: 1 | H28: 101.73 | I28: Store D | J28: Retail | K28: 0 | L28: Frank | M28: 101.73 | N28: Debit Card | O28: WINTER15 | P28: 0 | Q28: REG100026 | R28: Cust 2609 | S28: 11.59 | T28: 45824 | U28: 45833 | V28: Wendy | W28: =M28*(1-K28) -> 101.73 | X28: =G28*H28 -> 101.73 | Y28: =X28-W28 -> 0 | Z28: =IF(K28=0,"No Discount",IF(K28<5%,"Low",IF(K28<15%,"Medium","High"))) -> No Discount | AA28: =DATE(YEAR(Table1[[#This Row],[OrderDate]]),MONTH(Table1[[#This Row],[OrderDate]]),1) -> 45809
A29: 44988 | B29: North | C29: Phone | D29: =TRIM(Table1[[#This Row],[Product]]) -> Phone | E29: =PROPER(Table1[[#This Row],[Column1]]) -> Phone | F29: =IF(OR(E29="Chair",E29="Desk"),"Furniture",IF(OR(E29="Laptop",E29="Monitor",E29="Phone",E29="Tablet"),"Technology",IF(E29="Printer","Office Supplies","Other"))) -> Technology | G29: 4 | H29: 279.49 | I29: Store B | J29: Retail | K29: 0 | L29: Diana | M29: 1117.96 | N29: Credit Card | O29: FREESHIP | P29: 0 | Q29: REG100027 | R29: Cust 6880 | S29: 24.78 | T29: 44988 | U29: 44993 | V29: Ryan | W29: =M29*(1-K29) -> 1117.96 | X29: =G29*H29 -> 1117.96 | Y29: =X29-W29 -> 0 | Z29: =IF(K29=0,"No Discount",IF(K29<5%,"Low",IF(K29<15%,"Medium","High"))) -> No Discount | AA29: =DATE(YEAR(Table1[[#This Row],[OrderDate]]),MONTH(Table1[[#This Row],[OrderDate]]),1) -> 44986
A30: 45614 | B30: South | C30: Laptop | D30: =TRIM(Table1[[#This Row],[Product]]) -> Laptop | E30: =PROPER(Table1[[#This Row],[Column1]]) -> Laptop | F30: =IF(OR(E30="Chair",E30="Desk"),"Furniture",IF(OR(E30="Laptop",E30="Monitor",E30="Phone",E30="Tablet"),"Technology",IF(E30="Printer","Office Supplies","Other"))) -> Technology | G30: 1 | H30: 178.55 | I30: Store A | J30: Retail | K30: 0.15 | L30: Carlos | M30: 151.7675 | N30: Debit Card | O30: SAVE10 | P30: 1 | Q30: REG100028 | R30: Cust 1997 | S30: 7.61 | T30: 45614 | U30: 45617 | V30: Sophie | W30: =M30*(1-K30) -> 129.00238 | X30: =G30*H30 -> 178.55 | Y30: =X30-W30 -> 49.547625 | Z30: =IF(K30=0,"No Discount",IF(K30<5%,"Low",IF(K30<15%,"Medium","High"))) -> High | AA30: =DATE(YEAR(Table1[[#This Row],[OrderDate]]),MONTH(Table1[[#This Row],[OrderDate]]),1) -> 45597
A31: 45055 | B31: Central | C31: Tablet | D31: =TRIM(Table1[[#This Row],[Product]]) -> Tablet | E31: =PROPER(Table1[[#This Row],[Column1]]) -> Tablet | F31: =IF(OR(E31="Chair",E31="Desk"),"Furniture",IF(OR(E31="Laptop",E31="Monitor",E31="Phone",E31="Tablet"),"Technology",IF(E31="Printer","Office Supplies","Other"))) -> Technology | G31: 1 | H31: 472.07 | I31: Store A | J31: Wholesale | K31: 0.1 | L31: Carlos | M31: 424.863 | N31: Online | O31: FREESHIP | P31: 0 | Q31: REG100029 | R31: Cust 7072 | S31: 33.17 | T31: 45055 | U31: 45063 | V31: Cameron | W31: =M31*(1-K31) -> 382.3767 | X31: =G31*H31 -> 472.07 | Y31: =X31-W31 -> 89.6933 | Z31: =IF(K31=0,"No Discount",IF(K31<5%,"Low",IF(K31<15%,"Medium","High"))) -> Medium | AA31: =DATE(YEAR(Table1[[#This Row],[OrderDate]]),MONTH(Table1[[#This Row],[OrderDate]]),1) -> 45047
A32: 45633 | B32: North | C32: Tablet | D32: =TRIM(Table1[[#This Row],[Product]]) -> Tablet | E32: =PROPER(Table1[[#This Row],[Column1]]) -> Tablet | F32: =IF(OR(E32="Chair",E32="Desk"),"Furniture",IF(OR(E32="Laptop",E32="Monitor",E32="Phone",E32="Tablet"),"Technology",IF(E32="Printer","Office Supplies","Other"))) -> Technology | G32: 12 | H32: 306.29 | I32: Store D | J32: Retail | K32: 0 | L32: Frank | M32: 3675.48 | N32: Debit Card | O32: SAVE10 | P32: 0 | Q32: REG100030 | R32: Cust 7201 | S32: 37.38 | T32: 45633 | U32: 45640 | V32: Ryan | W32: =M32*(1-K32) -> 3675.48 | X32: =G32*H32 -> 3675.48 | Y32: =X32-W32 -> 0 | Z32: =IF(K32=0,"No Discount",IF(K32<5%,"Low",IF(K32<15%,"Medium","High"))) -> No Discount | AA32: =DATE(YEAR(Table1[[#This Row],[OrderDate]]),MONTH(Table1[[#This Row],[OrderDate]]),1) -> 45627
A33: 45335 | B33: North | C33: Phone | D33: =TRIM(Table1[[#This Row],[Product]]) -> Phone | E33: =PROPER(Table1[[#This Row],[Column1]]) -> Phone | F33: =IF(OR(E33="Chair",E33="Desk"),"Furniture",IF(OR(E33="Laptop",E33="Monitor",E33="Phone",E33="Tablet"),"Technology",IF(E33="Printer","Office Supplies","Other"))) -> Technology | G33: 7 | H33: 434.77 | I33: Store C | J33: Retail | K33: 0.15 | L33: Frank | M33: 2586.8815 | N33: Online | O33: SAVE10 | P33: 0 | Q33: REG100031 | R33: Cust 9923 | S33: 12.35 | T33: 45335 | U33: 45337 | V33: Ryan | W33: =M33*(1-K33) -> 2198.8493 | X33: =G33*H33 -> 3043.39 | Y33: =X33-W33 -> 844.54072 | Z33: =IF(K33=0,"No Discount",IF(K33<5%,"Low",IF(K33<15%,"Medium","High"))) -> High | AA33: =DATE(YEAR(Table1[[#This Row],[OrderDate]]),MONTH(Table1[[#This Row],[OrderDate]]),1) -> 45323
A34: 45725 | B34: South | C34: Desk | D34: =TRIM(Table1[[#This Row],[Product]]) -> Desk | E34: =PROPER(Table1[[#This Row],[Column1]]) -> Desk | F34: =IF(OR(E34="Chair",E34="Desk"),"Furniture",IF(OR(E34="Laptop",E34="Monitor",E34="Phone",E34="Tablet"),"Technology",IF(E34="Printer","Office Supplies","Other"))) -> Furniture | G34: 6 | H34: 64.98 | I34: Store C | J34: Retail | K34: 0 | L34: Carlos | M34: 389.88 | N34: Debit Card | O34: WINTER15 | P34: 0 | Q34: REG100032 | R34: Cust 2205 | S34: 21.25 | T34: 45725 | U34: 45731 | V34: Sophie | W34: =M34*(1-K34) -> 389.88 | X34: =G34*H34 -> 389.88 | Y34: =X34-W34 -> 0 | Z34: =IF(K34=0,"No Discount",IF(K34<5%,"Low",IF(K34<15%,"Medium","High"))) -> No Discount | AA34: =DATE(YEAR(Table1[[#This Row],[OrderDate]]),MONTH(Table1[[#This Row],[OrderDate]]),1) -> 45717
A35: 45021 | B35: Central | C35: Desk | D35: =TRIM(Table1[[#This Row],[Product]]) -> Desk | E35: =PROPER(Table1[[#This Row],[Column1]]) -> Desk | F35: =IF(OR(E35="Chair",E35="Desk"),"Furniture",IF(OR(E35="Laptop",E35="Monitor",E35="Phone",E35="Tablet"),"Technology",IF(E35="Printer","Office Supplies","Other"))) -> Furniture | G35: 17 | H35: 476.49 | I35: Store D | J35: Retail | K35: 0 | L35: Alice | M35: 8100.33 | N35: Gift Card | P35: 0 | Q35: REG100033 | R35: Cust 6403 | S35: 17.91 | T35: 45021 | U35: 45027 | V35: Cameron | W35: =M35*(1-K35) -> 8100.33 | X35: =G35*H35 -> 8100.33 | Y35: =X35-W35 -> 0 | Z35: =IF(K35=0,"No Discount",IF(K35<5%,"Low",IF(K35<15%,"Medium","High"))) -> No Discount | AA35: =DATE(YEAR(Table1[[#This Row],[OrderDate]]),MONTH(Table1[[#This Row],[OrderDate]]),1) -> 45017
A36: 45785 | B36: North | C36: Monitor | D36: =TRIM(Table1[[#This Row],[Product]]) -> Monitor | E36: =PROPER(Table1[[#This Row],[Column1]]) -> Monitor | F36: =IF(OR(E36="Chair",E36="Desk"),"Furniture",IF(OR(E36="Laptop",E36="Monitor",E36="Phone",E36="Tablet"),"Technology",IF(E36="Printer","Office Supplies","Other"))) -> Technology | G36: 4 | H36: 559.72 | I36: Store D | J36: Retail | K36: 0.15 | L36: Diana | M36: 1903.048 | N36: Online | O36: SAVE10 | P36: 0 | Q36: REG100034 | R36: Cust 3953 | S36: 41.91 | T36: 45785 | U36: 45789 | V36: Ryan | W36: =M36*(1-K36) -> 1617.5908 | X36: =G36*H36 -> 2238.88 | Y36: =X36-W36 -> 621.2892 | Z36: =IF(K36=0,"No Discount",IF(K36<5%,"Low",IF(K36<15%,"Medium","High"))) -> High | AA36: =DATE(YEAR(Table1[[#This Row],[OrderDate]]),MONTH(Table1[[#This Row],[OrderDate]]),1) -> 45778
A37: 45172 | B37: North | C37: Tablet | D37: =TRIM(Table1[[#This Row],[Product]]) -> Tablet | E37: =PROPER(Table1[[#This Row],[Column1]]) -> Tablet | F37: =IF(OR(E37="Chair",E37="Desk"),"Furniture",IF(OR(E37="Laptop",E37="Monitor",E37="Phone",E37="Tablet"),"Technology",IF(E37="Printer","Office Supplies","Other"))) -> Technology | G37: 14 | H37: 82.14 | I37: Store C | J37: Retail | K37: 0 | L37: Alice | M37: 1149.96 | N37: Credit Card | P37: 0 | Q37: REG100035 | R37: Cust 7902 | S37: 12.57 | T37: 45172 | U37: 45180 | V37: Ryan | W37: =M37*(1-K37) -> 1149.96 | X37: =G37*H37 -> 1149.96 | Y37: =X37-W37 -> 0 | Z37: =IF(K37=0,"No Discount",IF(K37<5%,"Low",IF(K37<15%,"Medium","High"))) -> No Discount | AA37: =DATE(YEAR(Table1[[#This Row],[OrderDate]]),MONTH(Table1[[#This Row],[OrderDate]]),1) -> 45170
A38: 45737 | B38: Central | C38: Chair | D38: =TRIM(Table1[[#This Row],[Product]]) -> Chair | E38: =PROPER(Table1[[#This Row],[Column1]]) -> Chair | F38: =IF(OR(E38="Chair",E38="Desk"),"Furniture",IF(OR(E38="Laptop",E38="Monitor",E38="Phone",E38="Tablet"),"Technology",IF(E38="Printer","Office Supplies","Other"))) -> Furniture | G38: 9 | H38: 343.21 | I38: Store A | J38: Retail | K38: 0.05 | L38: Carlos | M38: 2934.4455 | N38: Debit Card | O38: FREESHIP | P38: 0 | Q38: REG100036 | R38: Cust 9968 | S38: 40.29 | T38: 45737 | U38: 45744 | V38: Cameron | W38: =M38*(1-K38) -> 2787.7232 | X38: =G38*H38 -> 3088.89 | Y38: =X38-W38 -> 301.16678 | Z38: =IF(K38=0,"No Discount",IF(K38<5%,"Low",IF(K38<15%,"Medium","High"))) -> Medium | AA38: =DATE(YEAR(Table1[[#This Row],[OrderDate]]),MONTH(Table1[[#This Row],[OrderDate]]),1) -> 45717
A39: 45828 | B39: South | C39: Chair | D39: =TRIM(Table1[[#This Row],[Product]]) -> Chair | E39: =PROPER(Table1[[#This Row],[Column1]]) -> Chair | F39: =IF(OR(E39="Chair",E39="Desk"),"Furniture",IF(OR(E39="Laptop",E39="Monitor",E39="Phone",E39="Tablet"),"Technology",IF(E39="Printer","Office Supplies","Other"))) -> Furniture | G39: 7 | H39: 301.01 | I39: Store B | J39: Retail | K39: 0.15 | L39: Diana | M39: 1791.0095 | N39: Cash | O39: SAVE10 | P39: 1 | Q39: REG100037 | R39: Cust 3787 | S39: 34.97 | T39: 45828 | U39: 45838 | V39: Sophie | W39: =M39*(1-K39) -> 1522.3581 | X39: =G39*H39 -> 2107.07 | Y39: =X39-W39 -> 584.71192 | Z39: =IF(K39=0,"No Discount",IF(K39<5%,"Low",IF(K39<15%,"Medium","High"))) -> High | AA39: =DATE(YEAR(Table1[[#This Row],[OrderDate]]),MONTH(Table1[[#This Row],[OrderDate]]),1) -> 45809
A40: 45337 | B40: Central | C40: Printer | D40: =TRIM(Table1[[#This Row],[Product]]) -> Printer | E40: =PROPER(Table1[[#This Row],[Column1]]) -> Printer | F40: =IF(OR(E40="Chair",E40="Desk"),"Furniture",IF(OR(E40="Laptop",E40="Monitor",E40="Phone",E40="Tablet"),"Technology",IF(E40="Printer","Office Supplies","Other"))) -> Office Supplies | G40: 14 | H40: 428.13 | I40: Store C | J40: Retail | K40: 0.1 | L40: Bob | M40: 5394.438 | N40: Cash | P40: 1 | Q40: REG100038 | R40: Cust 2469 | S40: 24.77 | T40: 45337 | U40: 45347 | V40: Cameron | W40: =M40*(1-K40) -> 4854.9942 | X40: =G40*H40 -> 5993.82 | Y40: =X40-W40 -> 1138.8258 | Z40: =IF(K40=0,"No Discount",IF(K40<5%,"Low",IF(K40<15%,"Medium","High"))) -> Medium | AA40: =DATE(YEAR(Table1[[#This Row],[OrderDate]]),MONTH(Table1[[#This Row],[OrderDate]]),1) -> 45323
...

Sheet Pivot Data
A3: Total Sales | B3: Total Profit | C3: Total Orders | F3: Region | G3: Sum of Net Sales | H3: Sum of Profit | J3: Discount Category | K3: Sum of Profit
A4: 4072350.1 | B4: 655542.86 | C4: 1500 | D4: =GETPIVOTDATA("Total Profit",$A$3)/GETPIVOTDATA("Total Sales",$A$3) -> 0.16097409 | F4: Central | G4: 787211.78 | H4: 127575.2 | J4: No Discount | K4: 0
F5: East | G5: 827104.35 | H5: 120259.06 | J5: High | K5: 312142.17
F6: North | G6: 894607.17 | H6: 156474.61 | J6: Medium | K6: 343400.69
F7: South | G7: 770077.07 | H7: 123051.8 | J7: Grand Total | K7: 655542.86
A8: Years (Year-Month) | B8: Months (Year-Month) | C8: Sum of Net Sales | F8: West | G8: 793349.71 | H8: 128182.19
A9: 2023 | B9: Jan | C9: 145345.99 | F9: Grand Total | G9: 4072350.1 | H9: 655542.86 | J9: Salesperson | K9: Sum of Net Sales
B10: Feb | C10: 131509.56 | J10: Diana | K10: 626990.02
B11: Mar | C11: 188371.35 | J11: Eva | K11: 647454.24
B12: Apr | C12: 139489.97 | F12: Category | G12: Sum of Net Sales | J12: Carlos | K12: 654539.6
B13: May | C13: 108538.29 | F13: Furniture | G13: 1095216.7 | J13: Frank | K13: 663561.71
B14: Jun | C14: 126092.11 | F14: Office Supplies | G14: 632393.83 | J14: Alice | K14: 736279.13
B15: Jul | C15: 131292.93 | F15: Technology | G15: 2344739.6 | J15: Bob | K15: 743525.39
B16: Aug | C16: 149487.16 | F16: Grand Total | G16: 4072350.1 | J16: Grand Total | K16: 4072350.1
B17: Sep | C17: 141740.3
B18: Oct | C18: 72787.612
B19: Nov | C19: 134433.09
B20: Dec | C20: 111205.08 | F20: Product | G20: Sum of Profit
A21: 2023 Total | C21: 1580293.4 | F21: Phone | G21: 74306.793
A22: 2024 | B22: Jan | C22: 161397.95 | F22: Chair | G22: 87964.503
B23: Feb | C23: 126356.26 | F23: Desk | G23: 88243.92
B24: Mar | C24: 131192.8 | F24: Tablet | G24: 96417.503
B25: Apr | C25: 153705.86 | F25: Monitor | G25: 98011.144
B26: May | C26: 123703.11 | F26: Laptop | G26: 99487.012
B27: Jun | C27: 150316.26 | F27: Printer | G27: 111111.98
B28: Jul | C28: 129300.51 | F28: Grand Total | G28: 655542.86
B29: Aug | C29: 120083.84
B30: Sep | C30: 121676.03
B31: Oct | C31: 165124.53
B32: Nov | C32: 130480.49
B33: Dec | C33: 134562.41
A34: 2024 Total | C34: 1647900
A35: 2025 | B35: Jan | C35: 161275.03
B36: Feb | C36: 125728.24
B37: Mar | C37: 170017.68
B38: Apr | C38: 120345.08
B39: May | C39: 139774.58
B40: Jun | C40: 127015.99
A41: 2025 Total | C41: 844156.6
A42: Grand Total | C42: 4072350.1
